Workbook

Sheet Instruções
A1: Validação manual dos resultados do robô
A2: Gerada em 17/10/2026 a partir de: banco padrão. Linhas: 54 (critérios aplicáveis e automatizados da última coleta de cada entidade).
A4: Como preencher (aba 'Avaliação')
A5: 1. Colunas cinza = resultado do robô (não editar). Colunas amarelas = suas entradas.
A6: 2. Abra a URL da evidência (ou navegue pelo portal) e verifique o critério como um avaliador faria.
A7: 3. 'Status conferido': escolha na lista — atende, parcial, nao_atende, nao_aplicavel ou nao_verificavel (use nao_verificavel quando nem você conseguir concluir, ex.: portal fora do ar).
A8: 4. Se discordar do robô, escolha a 'Causa da divergência' e descreva em 'Observação'.
A9: 5. As colunas 'Classe', 'Par conclusivo' e 'Acerto exato' e toda a aba 'Métricas' são calculadas sozinhas.
A10: 6. Depois de ajustar regras, registre o que mudou na aba 'Ajustes' e reexecute: python -m src.pipeline reevaluate --latest (sem acessar os portais) e gere nova planilha.
A12: Classes calculadas
A13: Concordância: robô e você deram o mesmo status.
A14: Falso não atende: robô disse nao_atende, mas a informação existe (o erro mais grave numa fiscalização).
... A20: Linha de exemplo (formato esperado — não faz parte do cálculo)
A21: Entidade | B21: Avaliação nº | C21: Data da coleta | D21: Critério | E21: Descrição do critério | F21: Classificação | G21: Status do robô | H21: Confiança | I21: Conclusão do robô | J21: URL da evidência | K21: Trecho da evidência | L21: Status conferido | M21: URL onde conferiu | N21: Causa da divergência | O21: Observação
A22: Japeri | B22: 12 | C22: 2026-10-14 | D22: 4.1 | E22: Número e o valor de empenho, liquidação e pagamento | F22: essencial | G22: nao_atende | H22: 0.6 | I22: Não encontrado: dados de empenho/liquidação/pagamento... | J22: https://japeri.geosiap.net.br/portal-transparencia | L22: atende | M22: https://japeri.geosiap.net.br/portal-transparencia/despesas | N22: Informação em sistema externo/consulta | O22: Dados aparecem só após escolher o exercício no filtro.

Sheet Métricas
A1: Métricas de validação (atualizam conforme a aba 'Avaliação' é preenchida)
A2: Indicador | B2: Valor | C2: Como ler
A3: Linhas exportadas | B3: =COUNTA('Avaliação'!$G$2:$G$55) | C3: Critérios aplicáveis e automatizados exportados
A4: Linhas conferidas | B4: =COUNTIF('Avaliação'!$L$2:$L$55,"<>") | C4: Linhas com 'Status conferido' preenchido
A5: Progresso da conferência | B5: =IFERROR(B4/B3,0)
A6: Pares conclusivos | B6: =SUM('Avaliação'!$Q$2:$Q$55) | C6: Robô e humano com atende/parcial/nao_atende
A7: Concordância exata | B7: =IFERROR(SUM('Avaliação'!$R$2:$R$55)/B6,"—") | C7: Acertos / pares conclusivos
A8: Falsos 'não atende' | B8: =COUNTIF('Avaliação'!$P$2:$P$55,"Falso não atende") | C8: Erro mais grave: acusa ausência de informação existente
A9: Precisão do 'não atende' | B9: =IFERROR(COUNTIFS('Avaliação'!$G$2:$G$55,"nao_atende",'Avaliação'!$P$2:$P$55,"Concordância")/COUNTIFS('Avaliação'!$G$2:$G$55,"nao_atende",'Avaliação'!$Q$2:$Q$55,1),"—") | C9: Dos 'não atende' do robô conferidos, quantos estavam certos
A10: Falsos 'atende' | B10: =COUNTIF('Avaliação'!$P$2:$P$55,"Falso atende") | C10: Robô aceitou indício insuficiente
A11: Precisão do 'atende' | B11: =IFERROR(COUNTIFS('Avaliação'!$G$2:$G$55,"atende",'Avaliação'!$P$2:$P$55,"Concordância")/COUNTIFS('Avaliação'!$G$2:$G$55,"atende",'Avaliação'!$Q$2:$Q$55,1),"—") | C11: Dos 'atende' do robô conferidos, quantos estavam certos
A12: Divergências de grau | B12: =COUNTIF('Avaliação'!$P$2:$P$55,"Divergência de grau") | C12: Parcial × atende/não atende
A13: Taxa de inconclusivos (robô) | B13: =IFERROR(COUNTIF('Avaliação'!$G$2:$G$55,"inconclusivo")/B3,"—") | C13: Mede cobertura: quanto o robô não conseguiu decidir
A14: Inconclusivos que você resolveu | B14: =COUNTIFS('Avaliação'!$G$2:$G$55,"inconclusivo",'Avaliação'!$L$2:$L$55,"<>")-COUNTIFS('Avaliação'!$G$2:$G$55,"inconclusivo",'Avaliação'!$L$2:$L$55,"nao_verificavel") | C14: Potencial de ganho com renderização JS/novas regras
A15: Kappa de Cohen | B15: =IFERROR((B6*(B34+C35+D36)-(E34*B38+E35*C38+E36*D38))/(B6^2-(E34*B38+E35*C38+E36*D38)),"—") | C15: Concordância além do acaso nos pares conclusivos (>0,6 bom; >0,8 muito bom)
A32: Matriz de confusão — linhas: robô; colunas: conferência humana
A33: Robô \ Humano | B33: atende | C33: parcial | D33: nao_atende | E33: Total (pares) | F33: nao_aplicavel | G33: nao_verificavel | H33: não conferido
A34: atende | B34: =COUNTIFS('Avaliação'!$G$2:$G$55,"atende",'Avaliação'!$L$2:$L$55,"atende") | C34: =COUNTIFS('Avaliação'!$G$2:$G$55,"atende",'Avaliação'!$L$2:$L$55,"parcial") | D34: =COUNTIFS('Avaliação'!$G$2:$G$55,"atende",'Avaliação'!$L$2:$L$55,"nao_atende") | E34: =SUM(B34:D34) | F34: =COUNTIFS('Avaliação'!$G$2:$G$55,"atende",'Avaliação'!$L$2:$L$55,"nao_aplicavel") | G34: =COUNTIFS('Avaliação'!$G$2:$G$55,"atende",'Avaliação'!$L$2:$L$55,"nao_verificavel") | H34: =COUNTIF('Avaliação'!$G$2:$G$55,"atende")-COUNTIFS('Avaliação'!$G$2:$G$55,"atende",'Avaliação'!$L$2:$L$55,"<>")
A35: parcial | B35: =COUNTIFS('Avaliação'!$G$2:$G$55,"parcial",'Avaliação'!$L$2:$L$55,"atende") | C35: =COUNTIFS('Avaliação'!$G$2:$G$55,"parcial",'Avaliação'!$L$2:$L$55,"parcial") | D35: =COUNTIFS('Avaliação'!$G$2:$G$55,"parcial",'Avaliação'!$L$2:$L$55,"nao_atende") | E35: =SUM(B35:D35) | F35: =COUNTIFS('Avaliação'!$G$2:$G$55,"parcial",'Avaliação'!$L$2:$L$55,"nao_aplicavel") | G35: =COUNTIFS('Avaliação'!$G$2:$G$55,"parcial",'Avaliação'!$L$2:$L$55,"nao_verificavel") | H35: =COUNTIF('Avaliação'!$G$2:$G$55,"parcial")-COUNTIFS('Avaliação'!$G$2:$G$55,"parcial",'Avaliação'!$L$2:$L$55,"<>")
A36: nao_atende | B36: =COUNTIFS('Avaliação'!$G$2:$G$55,"nao_atende",'Avaliação'!$L$2:$L$55,"atende") | C36: =COUNTIFS('Avaliação'!$G$2:$G$55,"nao_atende",'Avaliação'!$L$2:$L$55,"parcial") | D36: =COUNTIFS('Avaliação'!$G$2:$G$55,"nao_atende",'Avaliação'!$L$2:$L$55,"nao_atende") | E36: =SUM(B36:D36) | F36: =COUNTIFS('Avaliação'!$G$2:$G$55,"nao_atende",'Avaliação'!$L$2:$L$55,"nao_aplicavel") | G36: =COUNTIFS('Avaliação'!$G$2:$G$55,"nao_atende",'Avaliação'!$L$2:$L$55,"nao_verificavel") | H36: =COUNTIF('Avaliação'!$G$2:$G$55,"nao_atende")-COUNTIFS('Avaliação'!$G$2:$G$55,"nao_atende",'Avaliação'!$L$2:$L$55,"<>")
A37: inconclusivo | B37: =COUNTIFS('Avaliação'!$G$2:$G$55,"inconclusivo",'Avaliação'!$L$2:$L$55,"atende") | C37: =COUNTIFS('Avaliação'!$G$2:$G$55,"inconclusivo",'Avaliação'!$L$2:$L$55,"parcial") | D37: =COUNTIFS('Avaliação'!$G$2:$G$55,"inconclusivo",'Avaliação'!$L$2:$L$55,"nao_atende") | F37: =COUNTIFS('Avaliação'!$G$2:$G$55,"inconclusivo",'Avaliação'!$L$2:$L$55,"nao_aplicavel") | G37: =COUNTIFS('Avaliação'!$G$2:$G$55,"inconclusivo",'Avaliação'!$L$2:$L$55,"nao_verificavel") | H37: =COUNTIF('Avaliação'!$G$2:$G$55,"inconclusivo")-COUNTIFS('Avaliação'!$G$2:$G$55,"inconclusivo",'Avaliação'!$L$2:$L$55,"<>")
A38: Total (pares) | B38: =SUM(B34:B36) | C38: =SUM(C34:C36) | D38: =SUM(D34:D36)
A41: Por critério (onde ajustar regras)
A42: Item | B42: Linhas | C42: Conferidas | D42: Pares conclusivos | E42: Concordância | F42: Falso não atende | G42: Falso atende | H42: Inconclusivos (robô)
A43: 1.1 | B43: =COUNTIF('Avaliação'!$D$2:$D$55,"1.1") | C43: =COUNTIFS('Avaliação'!$D$2:$D$55,"1.1",'Avaliação'!$L$2:$L$55,"<>") | D43: =COUNTIFS('Avaliação'!$D$2:$D$55,"1.1",'Avaliação'!$Q$2:$Q$55,1) | E43: =IFERROR(COUNTIFS('Avaliação'!$D$2:$D$55,"1.1",'Avaliação'!$R$2:$R$55,1)/D43,"—") | F43: =COUNTIFS('Avaliação'!$D$2:$D$55,"1.1",'Avaliação'!$P$2:$P$55,"Falso não atende") | G43: =COUNTIFS('Avaliação'!$D$2:$D$55,"1.1",'Avaliação'!$P$2:$P$55,"Falso atende") | H43: =COUNTIFS('Avaliação'!$D$2:$D$55,"1.1",'Avaliação'!$G$2:$G$55,"inconclusivo")
A44: 1.2 | B44: =COUNTIF('Avaliação'!$D$2:$D$55,"1.2") | C44: =COUNTIFS('Avaliação'!$D$2:$D$55,"1.2",'Avaliação'!$L$2:$L$55,"<>") | D44: =COUNTIFS('Avaliação'!$D$2:$D$55,"1.2",'Avaliação'!$Q$2:$Q$55,1) | E44: =IFERROR(COUNTIFS('Avaliação'!$D$2:$D$55,"1.2",'Avaliação'!$R$2:$R$55,1)/D44,"—") | F44: =COUNTIFS('Avaliação'!$D$2:$D$55,"1.2",'Avaliação'!$P$2:$P$55,"Falso não atende") | G44: =COUNTIFS('Avaliação'!$D$2:$D$55,"1.2",'Avaliação'!$P$2:$P$55,"Falso atende") | H44: =COUNTIFS('Avaliação'!$D$2:$D$55,"1.2",'Avaliação'!$G$2:$G$55,"inconclusivo")
A45: 1.3 | B45: =COUNTIF('Avaliação'!$D$2:$D$55,"1.3") | C45: =COUNTIFS('Avaliação'!$D$2:$D$55,"1.3",'Avaliação'!$L$2:$L$55,"<>") | D45: =COUNTIFS('Avaliação'!$D$2:$D$55,"1.3",'Avaliação'!$Q$2:$Q$55,1) | E45: =IFERROR(COUNTIFS('Avaliação'!$D$2:$D$55,"1.3",'Avaliação'!$R$2:$R$55,1)/D45,"—") | F45: =COUNTIFS('Avaliação'!$D$2:$D$55,"1.3",'Avaliação'!$P$2:$P$55,"Falso não atende") | G45: =COUNTIFS('Avaliação'!$D$2:$D$55,"1.3",'Avaliação'!$P$2:$P$55,"Falso atende") | H45: =COUNTIFS('Avaliação'!$D$2:$D$55,"1.3",'Avaliação'!$G$2:$G$55,"inconclusivo")
A46: 2.1 | B46: =COUNTIF('Avaliação'!$D$2:$D$55,"2.1") | C46: =COUNTIFS('Avaliação'!$D$2:$D$55,"2.1",'Avaliação'!$L$2:$L$55,"<>") | D46: =COUNTIFS('Avaliação'!$D$2:$D$55,"2.1",'Avaliação'!$Q$2:$Q$55,1) | E46: =IFERROR(COUNTIFS('Avaliação'!$D$2:$D$55,"2.1",'Avaliação'!$R$2:$R$55,1)/D46,"—") | F46: =COUNTIFS('Avaliação'!$D$2:$D$55,"2.1",'Avaliação'!$P$2:$P$55,"Falso não atende") | G46: =COUNTIFS('Avaliação'!$D$2:$D$55,"2.1",'Avaliação'!$P$2:$P$55,"Falso atende") | H46: =COUNTIFS('Avaliação'!$D$2:$D$55,"2.1",'Avaliação'!$G$2:$G$55,"inconclusivo")
A47: 2.4 | B47: =COUNTIF('Avaliação'!$D$2:$D$55,"2.4") | C47: =COUNTIFS('Avaliação'!$D$2:$D$55,"2.4",'Avaliação'!$L$2:$L$55,"<>") | D47: =COUNTIFS('Avaliação'!$D$2:$D$55,"2.4",'Avaliação'!$Q$2:$Q$55,1) | E47: =IFERROR(COUNTIFS('Avaliação'!$D$2:$D$55,"2.4",'Avaliação'!$R$2:$R$55,1)/D47,"—") | F47: =COUNTIFS('Avaliação'!$D$2:$D$55,"2.4",'Avaliação'!$P$2:$P$55,"Falso não atende") | G47: =COUNTIFS('Avaliação'!$D$2:$D$55,"2.4",'Avaliação'!$P$2:$P$55,"Falso atende") | H47: =COUNTIFS('Avaliação'!$D$2:$D$55,"2.4",'Avaliação'!$G$2:$G$55,"inconclusivo")
A48: 2.5 | B48: =COUNTIF('Avaliação'!$D$2:$D$55,"2.5") | C48: =COUNTIFS('Avaliação'!$D$2:$D$55,"2.5",'Avaliação'!$L$2:$L$55,"<>") | D48: =COUNTIFS('Avaliação'!$D$2:$D$55,"2.5",'Avaliação'!$Q$2:$Q$55,1) | E48: =IFERROR(COUNTIFS('Avaliação'!$D$2:$D$55,"2.5",'Avaliação'!$R$2:$R$55,1)/D48,"—") | F48: =COUNTIFS('Avaliação'!$D$2:$D$55,"2.5",'Avaliação'!$P$2:$P$55,"Falso não atende") | G48: =COUNTIFS('Avaliação'!$D$2:$D$55,"2.5",'Avaliação'!$P$2:$P$55,"Falso atende") | H48: =COUNTIFS('Avaliação'!$D$2:$D$55,"2.5",'Avaliação'!$G$2:$G$55,"inconclusivo")
A49: 2.6 | B49: =COUNTIF('Avaliação'!$D$2:$D$55,"2.6") | C49: =COUNTIFS('Avaliação'!$D$2:$D$55,"2.6",'Avaliação'!$L$2:$L$55,"<>") | D49: =COUNTIFS('Avaliação'!$D$2:$D$55,"2.6",'Avaliação'!$Q$2:$Q$55,1) | E49: =IFERROR(COUNTIFS('Avaliação'!$D$2:$D$55,"2.6",'Avaliação'!$R$2:$R$55,1)/D49,"—") | F49: =COUNTIFS('Avaliação'!$D$2:$D$55,"2.6",'Avaliação'!$P$2:$P$55,"Falso não atende") | G49: =COUNTIFS('Avaliação'!$D$2:$D$55,"2.6",'Avaliação'!$P$2:$P$55,"Falso atende") | H49: =COUNTIFS('Avaliação'!$D$2:$D$55,"2.6",'Avaliação'!$G$2:$G$55,"inconclusivo")
A50: 2.9 | B50: =COUNTIF('Avaliação'!$D$2:$D$55,"2.9") | C50: =COUNTIFS('Avaliação'!$D$2:$D$55,"2.9",'Avaliação'!$L$2:$L$55,"<>") | D50: =COUNTIFS('Avaliação'!$D$2:$D$55,"2.9",'Avaliação'!$Q$2:$Q$55,1) | E50: =IFERROR(COUNTIFS('Avaliação'!$D$2:$D$55,"2.9",'Avaliação'!$R$2:$R$55,1)/D50,"—") | F50: =COUNTIFS('Avaliação'!$D$2:$D$55,"2.9",'Avaliação'!$P$2:$P$55,"Falso não atende") | G50: =COUNTIFS('Avaliação'!$D$2:$D$55,"2.9",'Avaliação'!$P$2:$P$55,"Falso atende") | H50: =COUNTIFS('Avaliação'!$D$2:$D$55,"2.9",'Avaliação'!$G$2:$G$55,"inconclusivo")
A51: 3.1 | B51: =COUNTIF('Avaliação'!$D$2:$D$55,"3.1") | C51: =COUNTIFS('Avaliação'!$D$2:$D$55,"3.1",'Avaliação'!$L$2:$L$55,"<>") | D51: =COUNTIFS('Avaliação'!$D$2:$D$55,"3.1",'Avaliação'!$Q$2:$Q$55,1) | E51: =IFERROR(COUNTIFS('Avaliação'!$D$2:$D$55,"3.1",'Avaliação'!$R$2:$R$55,1)/D51,"—") | F51: =COUNTIFS('Avaliação'!$D$2:$D$55,"3.1",'Avaliação'!$P$2:$P$55,"Falso não atende") | G51: =COUNTIFS('Avaliação'!$D$2:$D$55,"3.1",'Avaliação'!$P$2:$P$55,"Falso atende") | H51: =COUNTIFS('Avaliação'!$D$2:$D$55,"3.1",'Avaliação'!$G$2:$G$55,"inconclusivo")
A52: 3.5 | B52: =COUNTIF('Avaliação'!$D$2:$D$55,"3.5") | C52: =COUNTIFS('Avaliação'!$D$2:$D$55,"3.5",'Avaliação'!$L$2:$L$55,"<>") | D52: =COUNTIFS('Avaliação'!$D$2:$D$55,"3.5",'Avaliação'!$Q$2:$Q$55,1) | E52: =IFERROR(COUNTIFS('Avaliação'!$D$2:$D$55,"3.5",'Avaliação'!$R$2:$R$55,1)/D52,"—") | F52: =COUNTIFS('Avaliação'!$D$2:$D$55,"3.5",'Avaliação'!$P$2:$P$55,"Falso não atende") | G52: =COUNTIFS('Avaliação'!$D$2:$D$55,"3.5",'Avaliação'!$P$2:$P$55,"Falso atende") | H52: =COUNTIFS('Avaliação'!$D$2:$D$55,"3.5",'Avaliação'!$G$2:$G$55,"inconclusivo")
A53: 4.1 | B53: =COUNTIF('Avaliação'!$D$2:$D$55,"4.1") | C53: =COUNTIFS('Avaliação'!$D$2:$D$55,"4.1",'Avaliação'!$L$2:$L$55,"<>") | D53: =COUNTIFS('Avaliação'!$D$2:$D$55,"4.1",'Avaliação'!$Q$2:$Q$55,1) | E53: =IFERROR(COUNTIFS('Avaliação'!$D$2:$D$55,"4.1",'Avaliação'!$R$2:$R$55,1)/D53,"—") | F53: =COUNTIFS('Avaliação'!$D$2:$D$55,"4.1",'Avaliação'!$P$2:$P$55,"Falso não atende") | G53: =COUNTIFS('Avaliação'!$D$2:$D$55,"4.1",'Avaliação'!$P$2:$P$55,"Falso atende") | H53: =COUNTIFS('Avaliação'!$D$2:$D$55,"4.1",'Avaliação'!$G$2:$G$55,"inconclusivo")
A54: 4.5 | B54: =COUNTIF('Avaliação'!$D$2:$D$55,"4.5") | C54: =COUNTIFS('Avaliação'!$D$2:$D$55,"4.5",'Avaliação'!$L$2:$L$55,"<>") | D54: =COUNTIFS('Avaliação'!$D$2:$D$55,"4.5",'Avaliação'!$Q$2:$Q$55,1) | E54: =IFERROR(COUNTIFS('Avaliação'!$D$2:$D$55,"4.5",'Avaliação'!$R$2:$R$55,1)/D54,"—") | F54: =COUNTIFS('Avaliação'!$D$2:$D$55,"4.5",'Avaliação'!$P$2:$P$55,"Falso não atende") | G54: =COUNTIFS('Avaliação'!$D$2:$D$55,"4.5",'Avaliação'!$P$2:$P$55,"Falso atende") | H54: =COUNTIFS('Avaliação'!$D$2:$D$55,"4.5",'Avaliação'!$G$2:$G$55,"inconclusivo")
A55: 4.6 | B55: =COUNTIF('Avaliação'!$D$2:$D$55,"4.6") | C55: =COUNTIFS('Avaliação'!$D$2:$D$55,"4.6",'Avaliação'!$L$2:$L$55,"<>") | D55: =COUNTIFS('Avaliação'!$D$2:$D$55,"4.6",'Avaliação'!$Q$2:$Q$55,1) | E55: =IFERROR(COUNTIFS('Avaliação'!$D$2:$D$55,"4.6",'Avaliação'!$R$2:$R$55,1)/D55,"—") | F55: =COUNTIFS('Avaliação'!$D$2:$D$55,"4.6",'Avaliação'!$P$2:$P$55,"Falso não atende") | G55: =COUNTIFS('Avaliação'!$D$2:$D$55,"4.6",'Avaliação'!$P$2:$P$55,"Falso atende") | H55: =COUNTIFS('Avaliação'!$D$2:$D$55,"4.6",'Avaliação'!$G$2:$G$55,"inconclusivo")
A56: 4.7 | B56: =COUNTIF('Avaliação'!$D$2:$D$55,"4.7") | C56: =COUNTIFS('Avaliação'!$D$2:$D$55,"4.7",'Avaliação'!$L$2:$L$55,"<>") | D56: =COUNTIFS('Avaliação'!$D$2:$D$55,"4.7",'Avaliação'!$Q$2:$Q$55,1) | E56: =IFERROR(COUNTIFS('Avaliação'!$D$2:$D$55,"4.7",'Avaliação'!$R$2:$R$55,1)/D56,"—") | F56: =COUNTIFS('Avaliação'!$D$2:$D$55,"4.7",'Avaliação'!$P$2:$P$55,"Falso não atende") | G56: =COUNTIFS('Avaliação'!$D$2:$D$55,"4.7",'Avaliação'!$P$2:$P$55,"Falso atende") | H56: =COUNTIFS('Avaliação'!$D$2:$D$55,"4.7",'Avaliação'!$G$2:$G$55,"inconclusivo")
A57: 12.1 | B57: =COUNTIF('Avaliação'!$D$2:$D$55,"12.1") | C57: =COUNTIFS('Avaliação'!$D$2:$D$55,"12.1",'Avaliação'!$L$2:$L$55,"<>") | D57: =COUNTIFS('Avaliação'!$D$2:$D$55,"12.1",'Avaliação'!$Q$2:$Q$55,1) | E57: =IFERROR(COUNTIFS('Avaliação'!$D$2:$D$55,"12.1",'Avaliação'!$R$2:$R$55,1)/D57,"—") | F57: =COUNTIFS('Avaliação'!$D$2:$D$55,"12.1",'Avaliação'!$P$2:$P$55,"Falso não atende") | G57: =COUNTIFS('Avaliação'!$D$2:$D$55,"12.1",'Avaliação'!$P$2:$P$55,"Falso atende") | H57: =COUNTIFS('Avaliação'!$D$2:$D$55,"12.1",'Avaliação'!$G$2:$G$55,"inconclusivo")
A58: 15.1 | B58: =COUNTIF('Avaliação'!$D$2:$D$55,"15.1") | C58: =COUNTIFS('Avaliação'!$D$2:$D$55,"15.1",'Avaliação'!$L$2:$L$55,"<>") | D58: =COUNTIFS('Avaliação'!$D$2:$D$55,"15.1",'Avaliação'!$Q$2:$Q$55,1) | E58: =IFERROR(COUNTIFS('Avaliação'!$D$2:$D$55,"15.1",'Avaliação'!$R$2:$R$55,1)/D58,"—") | F58: =COUNTIFS('Avaliação'!$D$2:$D$55,"15.1",'Avaliação'!$P$2:$P$55,"Falso não atende") | G58: =COUNTIFS('Avaliação'!$D$2:$D$55,"15.1",'Avaliação'!$P$2:$P$55,"Falso atende") | H58: =COUNTIFS('Avaliação'!$D$2:$D$55,"15.1",'Avaliação'!$G$2:$G$55,"inconclusivo")
...

Sheet Avaliação
A1: Entidade | B1: Avaliação nº | C1: Data da coleta | D1: Critério | E1: Descrição do critério | F1: Classificação | G1: Status do robô | H1: Confiança | I1: Conclusão do robô | J1: URL da evidência | K1: Trecho da evidência | L1: Status conferido | M1: URL onde conferiu | N1: Causa da divergência | O1: Observação | P1: Classe | Q1: Par conclusivo | R1: Acerto exato
A2: Japeri | B2: 45 | C2: 2026-10-17 | D2: 1.1 | E2: A entidade pública possui sítio oficial e/ou portal da transparência próprio ou compartilhado na internet? | F2: essencial | G2: atende | H2: 0.95 | I2: Sítio oficial e portal da transparência responderam (HTTP 200). | J2: https://japeri.rj.gov.br/ | K2: HTTP 200 | L2: atende | M2: https://japeri.rj.gov.br/ | P2: =IF(L2="","",IF(G2="inconclusivo","Inconclusivo",IF(L2="nao_aplicavel","Aplicabilidade",IF(L2="nao_verificavel","Não verificável",IF(G2=L2,"Concordância",IF(G2="nao_atende","Falso não atende",IF(G2="atende","Falso atende","Divergência de grau"))))))) | Q2: =IF(AND(OR(G2="atende",G2="parcial",G2="nao_atende"),OR(L2="atende",L2="parcial",L2="nao_atende")),1,0) | R2: =IF(Q2=1,IF(G2=L2,1,0),"")
A3: Japeri | B3: 45 | C3: 2026-10-17 | D3: 1.2 | E3: O acesso ao portal transparência está visível na capa do site? | F3: essencial | G3: atende | H3: 0.9 | I3: A capa contém 7 link(s) rotulado(s) 'Transparência'. Screenshot anexado. | J3: https://japeri.rj.gov.br/links/ | K3: Transparência | L3: atende | M3: https://japeri.rj.gov.br/links/ | P3: =IF(L3="","",IF(G3="inconclusivo","Inconclusivo",IF(L3="nao_aplicavel","Aplicabilidade",IF(L3="nao_verificavel","Não verificável",IF(G3=L3,"Concordância",IF(G3="nao_atende","Falso não atende",IF(G3="atende","Falso atende","Divergência de grau"))))))) | Q3: =IF(AND(OR(G3="atende",G3="parcial",G3="nao_atende"),OR(L3="atende",L3="parcial",L3="nao_atende")),1,0) | R3: =IF(Q3=1,IF(G3=L3,1,0),"")
A4: Japeri | B4: 45 | C4: 2026-10-17 | D4: 1.3 | E4: O site contém ferramenta de pesquisa de conteúdo que permita o acesso à informação? | F4: essencial | G4: atende | H4: 0.85 | I4: Campo de pesquisa encontrado. | J4: https://japeri.rj.gov.br/ | K4: campo 's' (text) | L4: atende | M4: https://japeri.rj.gov.br/ | P4: =IF(L4="","",IF(G4="inconclusivo","Inconclusivo",IF(L4="nao_aplicavel","Aplicabilidade",IF(L4="nao_verificavel","Não verificável",IF(G4=L4,"Concordância",IF(G4="nao_atende","Falso não atende",IF(G4="atende","Falso atende","Divergência de grau"))))))) | Q4: =IF(AND(OR(G4="atende",G4="parcial",G4="nao_atende"),OR(L4="atende",L4="parcial",L4="nao_atende")),1,0) | R4: =IF(Q4=1,IF(G4=L4,1,0),"")
A5: Japeri | B5: 45 | C5: 2026-10-17 | D5: 2.1 | E5: Competências e/ou atribuições | F5: obrigatoria | G5: atende | H5: 0.75 | I5: Página com título de competências/atribuições. | J5: https://japeri.geosiap.net.br/portal-transparencia/api-docs#!/RH_-_Servidores/get_rh_servidores_organograma | K5: , " codigo_cargo ": "string" } ] } Response Content Type application/json Parameters Parameter Value Description Parameter Type Data Type id_entidade ID da entidade a se efetuar a busca query integer competencia Data no formato AAAA-MM-DD query string Hide Response Curl Request URL Response Body Res | L5: atende | M5: https://japeri.rj.gov.br/team/secretaria-municipal-de-cultura/ | P5: =IF(L5="","",IF(G5="inconclusivo","Inconclusivo",IF(L5="nao_aplicavel","Aplicabilidade",IF(L5="nao_verificavel","Não verificável",IF(G5=L5,"Concordância",IF(G5="nao_atende","Falso não atende",IF(G5="atende","Falso atende","Divergência de grau"))))))) | Q5: =IF(AND(OR(G5="atende",G5="parcial",G5="nao_atende"),OR(L5="atende",L5="parcial",L5="nao_atende")),1,0) | R5: =IF(Q5=1,IF(G5=L5,1,0),"")
A6: Japeri | B6: 45 | C6: 2026-10-17 | D6: 2.4 | E6: Endereços | F6: obrigatoria | G6: atende | H6: 0.8 | I6: Endereço encontrado(s) em 'Prefeitura Municipal de Japeri'. | J6: https://japeri.rj.gov.br/ | K6: Tributos / Transparência Fazenda Digital Portal do Servidor Acesso a Informação Rua Francisco da Costa Filho, 1993 - Santa Inês (21) 3952-6610 - contato@japeri.rj.gov.br Home Sobre a Cidade Gove | L6: atende | M6: https://japeri.rj.gov.br/ | P6: =IF(L6="","",IF(G6="inconclusivo","Inconclusivo",IF(L6="nao_aplicavel","Aplicabilidade",IF(L6="nao_verificavel","Não verificável",IF(G6=L6,"Concordância",IF(G6="nao_atende","Falso não atende",IF(G6="atende","Falso atende","Divergência de grau"))))))) | Q6: =IF(AND(OR(G6="atende",G6="parcial",G6="nao_atende"),OR(L6="atende",L6="parcial",L6="nao_atende")),1,0) | R6: =IF(Q6=1,IF(G6=L6,1,0),"")
A7: Japeri | B7: 45 | C7: 2026-10-17 | D7: 2.5 | E7: Telefones | F7: obrigatoria | G7: atende | H7: 0.8 | I7: Telefone encontrado(s) em 'Prefeitura Municipal de Japeri'. | J7: https://japeri.rj.gov.br/ | K7: do Servidor Acesso a Informação Rua Francisco da Costa Filho, 1993 - Santa Inês (21) 3952-6610 - contato@japeri.rj.gov.br Home Sobre a Cidade Governo Prefeita Vice-Prefeito N | L7: atende | M7: https://japeri.rj.gov.br/ | P7: =IF(L7="","",IF(G7="inconclusivo","Inconclusivo",IF(L7="nao_aplicavel","Aplicabilidade",IF(L7="nao_verificavel","Não verificável",IF(G7=L7,"Concordância",IF(G7="nao_atende","Falso não atende",IF(G7="atende","Falso atende","Divergência de grau"))))))) | Q7: =IF(AND(OR(G7="atende",G7="parcial",G7="nao_atende"),OR(L7="atende",L7="parcial",L7="nao_atende")),1,0) | R7: =IF(Q7=1,IF(G7=L7,1,0),"")
A8: Japeri | B8: 45 | C8: 2026-10-17 | D8: 2.6 | E8: Horário de atendimento | F8: obrigatoria | G8: atende | H8: 0.75 | I8: Horário de atendimento encontrado(s) em 'Portal da Transparência'. | J8: https://japeri.geosiap.net.br/portal-transparencia | K8: @japeri.rj.gov.br Francisco da Costa Filho, Santa Inês JAPERI , RJ , 26381470 , 09:00 - 17:00 Página Inicial Painel COVID-19 SEI Saúde Execução Orçamentária Emendas Parlamen | L8: atende | M8: https://japeri.geosiap.net.br/portal-transparencia/ | P8: =IF(L8="","",IF(G8="inconclusivo","Inconclusivo",IF(L8="nao_aplicavel","Aplicabilidade",IF(L8="nao_verificavel","Não verificável",IF(G8=L8,"Concordância",IF(G8="nao_atende","Falso não atende",IF(G8="atende","Falso atende","Divergência de grau"))))))) | Q8: =IF(AND(OR(G8="atende",G8="parcial",G8="nao_atende"),OR(L8="atende",L8="parcial",L8="nao_atende")),1,0) | R8: =IF(Q8=1,IF(G8=L8,1,0),"")
A9: Japeri | B9: 45 | C9: 2026-10-17 | D9: 2.9 | E9: Canal de Comunicação com cidadão do tipo ‘Fale Conosco’, que permite ao interessado comunicar-se com órgão por via eletrônica ou telefônica | F9: obrigatoria | G9: atende | H9: 0.7 | I9: Link para canal de contato encontrado; formulário não verificado (pode estar em sistema externo). | J9: https://japeri.rj.gov.br/contato/ | K9: Contato | L9: atende | M9: https://japeri.rj.gov.br/contato/ | P9: =IF(L9="","",IF(G9="inconclusivo","Inconclusivo",IF(L9="nao_aplicavel","Aplicabilidade",IF(L9="nao_verificavel","Não verificável",IF(G9=L9,"Concordância",IF(G9="nao_atende","Falso não atende",IF(G9="atende","Falso atende","Divergência de grau"))))))) | Q9: =IF(AND(OR(G9="atende",G9="parcial",G9="nao_atende"),OR(L9="atende",L9="parcial",L9="nao_atende")),1,0) | R9: =IF(Q9=1,IF(G9=L9,1,0),"")
A10: Japeri | B10: 45 | C10: 2026-10-17 | D10: 3.1 | E10: Valores da receita pública arrecadada | F10: essencial | G10: atende | H10: 0.85 | I10: API pública do portal expõe receitas com valor arrecadado. | J10: https://japeri.geosiap.net.br/portal-transparencia/api/execucao/receitas/proprias/receitas_proprias?id_entidade=10&ano=2026&layout=anual | K10: 158 registros; campos: ds_plano_conta, vl_previsto, vl_total | L10: atende | M10: https://japeri.geosiap.net.br/portal-transparencia/ | P10: =IF(L10="","",IF(G10="inconclusivo","Inconclusivo",IF(L10="nao_aplicavel","Aplicabilidade",IF(L10="nao_verificavel","Não verificável",IF(G10=L10,"Concordância",IF(G10="nao_atende","Falso não atende",IF(G10="atende","Falso atende","Divergência de grau"))))))) | Q10: =IF(AND(OR(G10="atende",G10="parcial",G10="nao_atende"),OR(L10="atende",L10="parcial",L10="nao_atende")),1,0) | R10: =IF(Q10=1,IF(G10=L10,1,0),"")
A11: Japeri | B11: 45 | C11: 2026-10-17 | D11: 3.5 | E11: Gravação de relatórios em diversos formatos em relação aos critérios da receita | F11: obrigatoria | G11: parcial | H11: 0.7 | I11: Exportação de receita só em json. | J11: https://online.swagger.io/validator/debug?url=https://japeri.geosiap.net.br/portal-transparencia/api-docs/v1/swagger.json | L11: parcial | M11: https://japeri.geosiap.net.br/portal-transparencia/ | P11: =IF(L11="","",IF(G11="inconclusivo","Inconclusivo",IF(L11="nao_aplicavel","Aplicabilidade",IF(L11="nao_verificavel","Não verificável",IF(G11=L11,"Concordância",IF(G11="nao_atende","Falso não atende",IF(G11="atende","Falso atende","Divergência de grau"))))))) | Q11: =IF(AND(OR(G11="atende",G11="parcial",G11="nao_atende"),OR(L11="atende",L11="parcial",L11="nao_atende")),1,0) | R11: =IF(Q11=1,IF(G11=L11,1,0),"")
A12: Japeri | B12: 45 | C12: 2026-10-17 | D12: 4.1 | E12: Número e o valor de empenho, liquidação e pagamento | F12: essencial | G12: atende | H12: 0.85 | I12: API pública do portal expõe empenho, liquidação e pagamento. | J12: https://japeri.geosiap.net.br/portal-transparencia/api/execucao/empenhos/empenhos?id_entidade=10&ano=2026 | K12: 925 registros; campos: nr_empenho, vl_empenhado_per, vl_liquidado_per, vl_pago_per | L12: atende | M12: https://japeri.geosiap.net.br/portal-transparencia/ | P12: =IF(L12="","",IF(G12="inconclusivo","Inconclusivo",IF(L12="nao_aplicavel","Aplicabilidade",IF(L12="nao_verificavel","Não verificável",IF(G12=L12,"Concordância",IF(G12="nao_atende","Falso não atende",IF(G12="atende","Falso atende","Divergência de grau"))))))) | Q12: =IF(AND(OR(G12="atende",G12="parcial",G12="nao_atende"),OR(L12="atende",L12="parcial",L12="nao_atende")),1,0) | R12: =IF(Q12=1,IF(G12=L12,1,0),"")
A13: Japeri | B13: 45 | C13: 2026-10-17 | D13: 4.5 | E13: Gravação de relatórios em diversos formatos em relação aos critérios da despesa | F13: obrigatoria | G13: parcial | H13: 0.7 | I13: Exportação de despesa só em json. | J13: https://online.swagger.io/validator/debug?url=https://japeri.geosiap.net.br/portal-transparencia/api-docs/v1/swagger.json | L13: parcial | M13: https://japeri.geosiap.net.br/portal-transparencia/ | P13: =IF(L13="","",IF(G13="inconclusivo","Inconclusivo",IF(L13="nao_aplicavel","Aplicabilidade",IF(L13="nao_verificavel","Não verificável",IF(G13=L13,"Concordância",IF(G13="nao_atende","Falso não atende",IF(G13="atende","Falso atende","Divergência de grau"))))))) | Q13: =IF(AND(OR(G13="atende",G13="parcial",G13="nao_atende"),OR(L13="atende",L13="parcial",L13="nao_atende")),1,0) | R13: =IF(Q13=1,IF(G13=L13,1,0),"")
A14: Japeri | B14: 45 | C14: 2026-10-17 | D14: 4.6 | E14: Existência de informações atualizadas em relação aos critérios da despesa | F14: obrigatoria | G14: inconclusivo | H14: 0.35 | I14: Páginas de despesa sem datas legíveis no HTML (datas podem estar em consulta dinâmica). | J14: https://japeri.geosiap.net.br/portal-transparencia/api-docs#!/Execucao_-_Despesas_Detalhadas/get_execucao_despesas_detalhadas_empenhos | L14: parcial | M14: https://japeri.geosiap.net.br/portal-transparencia/ | N14: Conteúdo dinâmico (JavaScript) | O14: Portal indica dados atualizados em 17/10/2026; a data de cada registro de despesa não pôde ser conferida na consulta dinâmica. | P14: =IF(L14="","",IF(G14="inconclusivo","Inconclusivo",IF(L14="nao_aplicavel","Aplicabilidade",IF(L14="nao_verificavel","Não verificável",IF(G14=L14,"Concordância",IF(G14="nao_atende","Falso não atende",IF(G14="atende","Falso atende","Divergência de grau"))))))) | Q14: =IF(AND(OR(G14="atende",G14="parcial",G14="nao_atende"),OR(L14="atende",L14="parcial",L14="nao_atende")),1,0) | R14: =IF(Q14=1,IF(G14=L14,1,0),"")
A15: Japeri | B15: 45 | C15: 2026-10-17 | D15: 4.7 | E15: Existência de histórico das informações em relação aos critérios da despesa | F15: obrigatoria | G15: inconclusivo | H15: 0.4 | I15: Seletor de exercício não identificado no HTML. | J15: https://japeri.geosiap.net.br/portal-transparencia/api-docs#!/Execucao_-_Despesas_Detalhadas/get_execucao_despesas_detalhadas_empenhos | L15: atende | M15: https://japeri.geosiap.net.br/portal-transparencia/ | N15: Crawler não chegou à página | O15: O menu apresenta despesas anteriores a 2018, bem como consultas do exercício. Histórico de despesas identificado. | P15: =IF(L15="","",IF(G15="inconclusivo","Inconclusivo",IF(L15="nao_aplicavel","Aplicabilidade",IF(L15="nao_verificavel","Não verificável",IF(G15=L15,"Concordância",IF(G15="nao_atende","Falso não atende",IF(G15="atende","Falso atende","Divergência de grau"))))))) | Q15: =IF(AND(OR(G15="atende",G15="parcial",G15="nao_atende"),OR(L15="atende",L15="parcial",L15="nao_atende")),1,0) | R15: =IF(Q15=1,IF(G15=L15,1,0),"")
A16: Japeri | B16: 45 | C16: 2026-10-17 | D16: 12.1 | E16: Publica o Relatório de Gestão Fiscal (RGF) | F16: essencial | G16: parcial | H16: 0.5 | I16: Relatório de Gestão Fiscal citado no portal (item de menu ou texto), sem link navegável nem arquivo alcançado: provável consulta dinâmica. | J16: https://japeri.geosiap.net.br/portal-transparencia | K16: mentária Anual launch RREO - Relatório Resumido da Execução Orçamentária launch RGF - Relatório de Gestão Fiscal launch Obras - Data de Início, Etapas, Percentual, | L16: parcial | M16: https://japeri.geosiap.net.br/portal-transparencia/publicacoes | N16: Crawler não chegou à página | O16: O menu do portal oferece RGF, mas não foi possível verificar o conteúdo e a abrangência dos arquivos na consulta dinâmica. | P16: =IF(L16="","",IF(G16="inconclusivo","Inconclusivo",IF(L16="nao_aplicavel","Aplicabilidade",IF(L16="nao_verificavel","Não verificável",IF(G16=L16,"Concordância",IF(G16="nao_atende","Falso não atende",IF(G16="atende","Falso atende","Divergência de grau"))))))) | Q16: =IF(AND(OR(G16="atende",G16="parcial",G16="nao_atende"),OR(L16="atende",L16="parcial",L16="nao_atende")),1,0) | R16: =IF(Q16=1,IF(G16=L16,1,0),"")
A17: Japeri | B17: 45 | C17: 2026-10-17 | D17: 15.1 | E17: Há possibilidade de envio de pedidos de informação de forma eletrônica (e­SIC) | F17: essencial | G17: inconclusivo | H17: 0.4 | I17: Não encontrado: Acesso ao e-SIC, mas o limite de páginas acabou com 7 link(s) de sic ainda não visitados. Ausência não pode ser afirmada (aumentar max_paginas para a entidade). | J17: https://japeri.rj.gov.br/ | L17: atende | M17: https://japeri.rj.gov.br/service/sic-presencial/ | N17: Crawler não chegou à página | O17: A página oficial leva ao Fala.BR para manifestações eletrônicas; também há acesso ao SIC no portal de transparência. Envio não realizado. | P17: =IF(L17="","",IF(G17="inconclusivo","Inconclusivo",IF(L17="nao_aplicavel","Aplicabilidade",IF(L17="nao_verificavel","Não verificável",IF(G17=L17,"Concordância",IF(G17="nao_atende","Falso não atende",IF(G17="atende","Falso atende","Divergência de grau"))))))) | Q17: =IF(AND(OR(G17="atende",G17="parcial",G17="nao_atende"),OR(L17="atende",L17="parcial",L17="nao_atende")),1,0) | R17: =IF(Q17=1,IF(G17=L17,1,0),"")
A18: Japeri | B18: 45 | C18: 2026-10-17 | D18: 15.2 | E18: A solicitação por meio do e­SIC é simples, ou seja, sem a exigência de itens de identificação do requerente que dificultem ou impossibilitem o acesso à informação, tais como: envio de documentos, assinatura reconhecida, declaração de responsabilidade, maioridade. *A exigência de cadastro prévio não configura dificuldade ou impossibilidade de acesso à informação. | F18: obrigatoria | G18: inconclusivo | H18: 0.35 | I18: Formulário do e-SIC não acessível ao robô (sistema externo ou login). Exigências precisam de leitura do texto. | J18: https://japeri.rj.gov.br/service/acesso-a-informacao/ | L18: nao_verificavel | M18: https://japeri.geosiap.net.br/pmjaperi/websis/portal_transparencia/sic/formulario.php?c=1792241802 | P18: =IF(L18="","",IF(G18="inconclusivo","Inconclusivo",IF(L18="nao_aplicavel","Aplicabilidade",IF(L18="nao_verificavel","Não verificável",IF(G18=L18,"Concordância",IF(G18="nao_atende","Falso não atende",IF(G18="atende","Falso atende","Divergência de grau"))))))) | Q18: =IF(AND(OR(G18="atende",G18="parcial",G18="nao_atende"),OR(L18="atende",L18="parcial",L18="nao_atende")),1,0) | R18: =IF(Q18=1,IF(G18=L18,1,0),"")
A19: Japeri | B19: 45 | C19: 2026-10-17 | D19: 15.4 | E19: Divulga, na seção relativa ao e-SIC, os prazos de resposta ao cidadão, incluindo o recursal, e as autoridades competentes para o exame dos pedidos, além do procedimento referente à realização do pedido e de eventual recurso? | F19: obrigatoria | G19: inconclusivo | H19: 0.4 | I19: Não encontrado: Prazos e procedimento do e-SIC, mas o limite de páginas acabou com 7 link(s) de sic ainda não visitados. Ausência não pode ser afirmada (aumentar max_paginas para a entidade). | J19: https://japeri.rj.gov.br/service/acesso-a-informacao/ | L19: parcial | M19: https://siapegov.japeri.rj.gov.br/pmjaperi/websis/portal_transparencia/sic/perguntas.php?c=1624608557&id=1 | N19: Crawler não chegou à página | O19: FAQ do SIC inclui prazo de resposta; não foi possível confirmar no mesmo fluxo todas as autoridades e etapas recursais exigidas. | P19: =IF(L19="","",IF(G19="inconclusivo","Inconclusivo",IF(L19="nao_aplicavel","Aplicabilidade",IF(L19="nao_verificavel","Não verificável",IF(G19=L19,"Concordância",IF(G19="nao_atende","Falso não atende",IF(G19="atende","Falso atende","Divergência de grau"))))))) | Q19: =IF(AND(OR(G19="atende",G19="parcial",G19="nao_atende"),OR(L19="atende",L19="parcial",L19="nao_atende")),1,0) | R19: =IF(Q19=1,IF(G19=L19,1,0),"")
A20: Japeri | B20: 45 | C20: 2026-10-17 | D20: 16.1 | E20: Exibição do “caminho” de páginas percorridas pelo usuário | F20: obrigatoria | G20: nao_atende | H20: 0.65 | I20: Não encontrado: Trilha de navegação. Foram examinadas 80 páginas (temas cobertos: contrato, dados_abertos, despesa, diarias, institucional, licitacao, obras, ouvidoria, pessoal, receita, sic, transparencia). | J20: https://japeri.geosiap.net.br/pmjaperi/websis/siapegov/administrativo/aten/aten_valida.php | L20: atende | M20: https://japeri.geosiap.net.br/portal-transparencia/covid-19/despesas | N20: Regra: falso indício | O20: Página interna do portal exibe trilha «Painel COVID-19 » Despesas Realizadas». | P20: =IF(L20="","",IF(G20="inconclusivo","Inconclusivo",IF(L20="nao_aplicavel","Aplicabilidade",IF(L20="nao_verificavel","Não verificável",IF(G20=L20,"Concordância",IF(G20="nao_atende","Falso não atende",IF(G20="atende","Falso atende","Divergência de grau"))))))) | Q20: =IF(AND(OR(G20="atende",G20="parcial",G20="nao_atende"),OR(L20="atende",L20="parcial",L20="nao_atende")),1,0) | R20: =IF(Q20=1,IF(G20=L20,1,0),"")
A21: Japeri | B21: 45 | C21: 2026-10-17 | D21: 16.2 | E21: Opção de alto contraste | F21: obrigatoria | G21: parcial | H21: 0.7 | I21: Controle de alto contraste encontrado em 1 de 2 página(s) inicial(is) (sítio/portal). | J21: https://japeri.geosiap.net.br/portal-transparencia | K21: Alto Contraste [['linkAcessibilidade']] | L21: parcial | M21: https://japeri.geosiap.net.br/portal-transparencia/ | P21: =IF(L21="","",IF(G21="inconclusivo","Inconclusivo",IF(L21="nao_aplicavel","Aplicabilidade",IF(L21="nao_verificavel","Não verificável",IF(G21=L21,"Concordância",IF(G21="nao_atende","Falso não atende",IF(G21="atende","Falso atende","Divergência de grau"))))))) | Q21: =IF(AND(OR(G21="atende",G21="parcial",G21="nao_atende"),OR(L21="atende",L21="parcial",L21="nao_atende")),1,0) | R21: =IF(Q21=1,IF(G21=L21,1,0),"")
A22: Japeri | B22: 45 | C22: 2026-10-17 | D22: 16.3 | E22: Ferramenta de redimensionamento de texto | F22: obrigatoria | G22: parcial | H22: 0.7 | I22: Redimensionamento de texto encontrado em 1 de 2 página(s) inicial(is) (sítio/portal). | J22: https://japeri.geosiap.net.br/portal-transparencia | K22: A- [['linkAcessibilidade']] | L22: parcial | M22: https://japeri.geosiap.net.br/portal-transparencia/ | P22: =IF(L22="","",IF(G22="inconclusivo","Inconclusivo",IF(L22="nao_aplicavel","Aplicabilidade",IF(L22="nao_verificavel","Não verificável",IF(G22=L22,"Concordância",IF(G22="nao_atende","Falso não atende",IF(G22="atende","Falso atende","Divergência de grau"))))))) | Q22: =IF(AND(OR(G22="atende",G22="parcial",G22="nao_atende"),OR(L22="atende",L22="parcial",L22="nao_atende")),1,0) | R22: =IF(Q22=1,IF(G22=L22,1,0),"")
A23: Japeri | B23: 45 | C23: 2026-10-17 | D23: 18.1 | E23: Identifica o encarregado/responsável pelo tratamento de dados pessoais e disponibiliza Canal de Comunicação (telefone e/ou e-mail) | F23: recomendada | G23: inconclusivo | H23: 0.4 | I23: Não encontrado: Identificação do encarregado (LGPD), mas o limite de páginas acabou com 1 link(s) de lgpd ainda não visitados. Ausência não pode ser afirmada (aumentar max_paginas para a entidade). | J23: https://japeri.rj.gov.br/ | L23: nao_verificavel | M23: https://japeri.geosiap.net.br/portal-transparencia/ | P23: =IF(L23="","",IF(G23="inconclusivo","Inconclusivo",IF(L23="nao_aplicavel","Aplicabilidade",IF(L23="nao_verificavel","Não verificável",IF(G23=L23,"Concordância",IF(G23="nao_atende","Falso não atende",IF(G23="atende","Falso atende","Divergência de grau"))))))) | Q23: =IF(AND(OR(G23="atende",G23="parcial",G23="nao_atende"),OR(L23="atende",L23="parcial",L23="nao_atende")),1,0) | R23: =IF(Q23=1,IF(G23=L23,1,0),"")
A24: Japeri | B24: 45 | C24: 2026-10-17 | D24: 18.3 | E24: Possibilita o acesso automatizado por sistemas externos em dados abertos (estruturados e legíveis por máquina), e a página contém as regras de utilização | F24: recomendada | G24: parcial | H24: 0.7 | I24: Há dados legíveis por máquina, mas não foram localizadas as regras de utilização. | J24: https://online.swagger.io/validator/debug?url=https://japeri.geosiap.net.br/portal-transparencia/api-docs/v1/swagger.json | L24: parcial | M24: https://japeri.geosiap.net.br/portal-transparencia/ | P24: =IF(L24="","",IF(G24="inconclusivo","Inconclusivo",IF(L24="nao_aplicavel","Aplicabilidade",IF(L24="nao_verificavel","Não verificável",IF(G24=L24,"Concordância",IF(G24="nao_atende","Falso não atende",IF(G24="atende","Falso atende","Divergência de grau"))))))) | Q24: =IF(AND(OR(G24="atende",G24="parcial",G24="nao_atende"),OR(L24="atende",L24="parcial",L24="nao_atende")),1,0) | R24: =IF(Q24=1,IF(G24=L24,1,0),"")
A25: Japeri | B25: 45 | C25: 2026-10-17 | D25: 19.1 | E25: Existência de PPA (Lei do Plano Plurianual) | F25: essencial | G25: parcial | H25: 0.5 | I25: PPA citado no portal (item de menu ou texto), sem link navegável nem arquivo alcançado: provável consulta dinâmica. | J25: https://japeri.geosiap.net.br/portal-transparencia | K25: Parecer do Tribunal de Contas launch Relatório Circunstanciado de Gestão launch PPA - Planejamento Plurianual launch LDO - Lei de Diretrizes Orçamentárias launch L | L25: parcial | M25: https://japeri.geosiap.net.br/portal-transparencia/publicacoes | N25: Crawler não chegou à página | O25: O menu contém PPA - Planejamento Plurianual; a consulta de arquivos não pôde ser concluída. | P25: =IF(L25="","",IF(G25="inconclusivo","Inconclusivo",IF(L25="nao_aplicavel","Aplicabilidade",IF(L25="nao_verificavel","Não verificável",IF(G25=L25,"Concordância",IF(G25="nao_atende","Falso não atende",IF(G25="atende","Falso atende","Divergência de grau"))))))) | Q25: =IF(AND(OR(G25="atende",G25="parcial",G25="nao_atende"),OR(L25="atende",L25="parcial",L25="nao_atende")),1,0) | R25: =IF(Q25=1,IF(G25=L25,1,0),"")
A26: Japeri | B26: 45 | C26: 2026-10-17 | D26: 19.3 | E26: Existência de LDO (Lei do Diretrizes Orçamentárias) | F26: essencial | G26: parcial | H26: 0.5 | I26: LDO citado no portal (item de menu ou texto), sem link navegável nem arquivo alcançado: provável consulta dinâmica. | J26: https://japeri.geosiap.net.br/portal-transparencia | K26: Relatório Circunstanciado de Gestão launch PPA - Planejamento Plurianual launch LDO - Lei de Diretrizes Orçamentárias launch LOA - Lei Orçamentária Anual launch RR | L26: parcial | M26: https://japeri.geosiap.net.br/portal-transparencia/publicacoes | N26: Crawler não chegou à página | O26: O menu contém LDO - Lei de Diretrizes Orçamentárias; a consulta de arquivos não pôde ser concluída. | P26: =IF(L26="","",IF(G26="inconclusivo","Inconclusivo",IF(L26="nao_aplicavel","Aplicabilidade",IF(L26="nao_verificavel","Não verificável",IF(G26=L26,"Concordância",IF(G26="nao_atende","Falso não atende",IF(G26="atende","Falso atende","Divergência de grau"))))))) | Q26: =IF(AND(OR(G26="atende",G26="parcial",G26="nao_atende"),OR(L26="atende",L26="parcial",L26="nao_atende")),1,0) | R26: =IF(Q26=1,IF(G26=L26,1,0),"")
A27: Japeri | B27: 45 | C27: 2026-10-17 | D27: 19.5 | E27: Existência de LOA (Lei Orçamentária) | F27: essencial | G27: parcial | H27: 0.5 | I27: LOA citado no portal (item de menu ou texto), sem link navegável nem arquivo alcançado: provável consulta dinâmica. | J27: https://japeri.geosiap.net.br/portal-transparencia | K27: A - Planejamento Plurianual launch LDO - Lei de Diretrizes Orçamentárias launch LOA - Lei Orçamentária Anual launch RREO - Relatório Resumido da Execução Orçamentá | L27: parcial | M27: https://japeri.geosiap.net.br/portal-transparencia/publicacoes | N27: Crawler não chegou à página | O27: O menu contém LOA - Lei Orçamentária Anual; a consulta de arquivos não pôde ser concluída. | P27: =IF(L27="","",IF(G27="inconclusivo","Inconclusivo",IF(L27="nao_aplicavel","Aplicabilidade",IF(L27="nao_verificavel","Não verificável",IF(G27=L27,"Concordância",IF(G27="nao_atende","Falso não atende",IF(G27="atende","Falso atende","Divergência de grau"))))))) | Q27: =IF(AND(OR(G27="atende",G27="parcial",G27="nao_atende"),OR(L27="atende",L27="parcial",L27="nao_atende")),1,0) | R27: =IF(Q27=1,IF(G27=L27,1,0),"")
A28: Japeri | B28: 45 | C28: 2026-10-17 | D28: 20.1 | E28: Relatório Resumido da Execução Orçamentária (RREO) | F28: essencial | G28: parcial | H28: 0.5 | I28: RREO citado no portal (item de menu ou texto), sem link navegável nem arquivo alcançado: provável consulta dinâmica. | J28: https://japeri.geosiap.net.br/portal-transparencia | K28: DO - Lei de Diretrizes Orçamentárias launch LOA - Lei Orçamentária Anual launch RREO - Relatório Resumido da Execução Orçamentária launch RGF - Relatório de Gestão | L28: parcial | M28: https://japeri.geosiap.net.br/portal-transparencia/publicacoes | N28: Crawler não chegou à página | O28: O menu contém RREO - Relatório Resumido da Execução Orçamentária; a consulta de arquivos não pôde ser concluída. | P28: =IF(L28="","",IF(G28="inconclusivo","Inconclusivo",IF(L28="nao_aplicavel","Aplicabilidade",IF(L28="nao_verificavel","Não verificável",IF(G28=L28,"Concordância",IF(G28="nao_atende","Falso não atende",IF(G28="atende","Falso atende","Divergência de grau"))))))) | Q28: =IF(AND(OR(G28="atende",G28="parcial",G28="nao_atende"),OR(L28="atende",L28="parcial",L28="nao_atende")),1,0) | R28: =IF(Q28=1,IF(G28=L28,1,0),"")
A29: Rio de Janeiro | B29: 44 | C29: 2026-10-17 | D29: 1.1 | E29: A entidade pública possui sítio oficial e/ou portal da transparência próprio ou compartilhado na internet? | F29: essencial | G29: atende | H29: 0.95 | I29: Sítio oficial e portal da transparência responderam (HTTP 200). | J29: https://prefeitura.rio/ | K29: HTTP 200 | L29: atende | M29: https://prefeitura.rio/ | P29: =IF(L29="","",IF(G29="inconclusivo","Inconclusivo",IF(L29="nao_aplicavel","Aplicabilidade",IF(L29="nao_verificavel","Não verificável",IF(G29=L29,"Concordância",IF(G29="nao_atende","Falso não atende",IF(G29="atende","Falso atende","Divergência de grau"))))))) | Q29: =IF(AND(OR(G29="atende",G29="parcial",G29="nao_atende"),OR(L29="atende",L29="parcial",L29="nao_atende")),1,0) | R29: =IF(Q29=1,IF(G29=L29,1,0),"")
A30: Rio de Janeiro | B30: 44 | C30: 2026-10-17 | D30: 1.2 | E30: O acesso ao portal transparência está visível na capa do site? | F30: essencial | G30: atende | H30: 0.8 | I30: A capa contém 3 link(s) rotulado(s) 'Transparência'. Destaque visual não verificado (sem renderização). | J30: https://transparencia.prefeitura.rio | K30: Transparência Rio | L30: atende | M30: https://transparencia.prefeitura.rio/ | P30: =IF(L30="","",IF(G30="inconclusivo","Inconclusivo",IF(L30="nao_aplicavel","Aplicabilidade",IF(L30="nao_verificavel","Não verificável",IF(G30=L30,"Concordância",IF(G30="nao_atende","Falso não atende",IF(G30="atende","Falso atende","Divergência de grau"))))))) | Q30: =IF(AND(OR(G30="atende",G30="parcial",G30="nao_atende"),OR(L30="atende",L30="parcial",L30="nao_atende")),1,0) | R30: =IF(Q30=1,IF(G30=L30,1,0),"")
A31: Rio de Janeiro | B31: 44 | C31: 2026-10-17 | D31: 1.3 | E31: O site contém ferramenta de pesquisa de conteúdo que permita o acesso à informação? | F31: essencial | G31: atende | H31: 0.85 | I31: Campo de pesquisa encontrado. | J31: https://prefeitura.rio/ | K31: campo 's' (search) | L31: atende | M31: https://prefeitura.rio/ | P31: =IF(L31="","",IF(G31="inconclusivo","Inconclusivo",IF(L31="nao_aplicavel","Aplicabilidade",IF(L31="nao_verificavel","Não verificável",IF(G31=L31,"Concordância",IF(G31="nao_atende","Falso não atende",IF(G31="atende","Falso atende","Divergência de grau"))))))) | Q31: =IF(AND(OR(G31="atende",G31="parcial",G31="nao_atende"),OR(L31="atende",L31="parcial",L31="nao_atende")),1,0) | R31: =IF(Q31=1,IF(G31=L31,1,0),"")
A32: Rio de Janeiro | B32: 44 | C32: 2026-10-17 | D32: 2.1 | E32: Competências e/ou atribuições | F32: obrigatoria | G32: atende | H32: 0.75 | I32: Página com título de competências/atribuições. | J32: https://transparencia.prefeitura.rio/perguntas-frequentes/ | K32: ento ao Cidadão. O contribuinte pode entrar em contato por meio do telefone 1746, pelo portal https://www.1746.rio/ ou pelo Aplicativo 1746 (disponível para Android e iOS). 6. Onde posso encontrar as competências dos órgãos da Prefeitura do Rio? A consulta de todos os órgãos da Prefeitura, sua local | L32: atende | M32: https://transparencia.prefeitura.rio/perguntas-frequentes/ | P32: =IF(L32="","",IF(G32="inconclusivo","Inconclusivo",IF(L32="nao_aplicavel","Aplicabilidade",IF(L32="nao_verificavel","Não verificável",IF(G32=L32,"Concordância",IF(G32="nao_atende","Falso não atende",IF(G32="atende","Falso atende","Divergência de grau"))))))) | Q32: =IF(AND(OR(G32="atende",G32="parcial",G32="nao_atende"),OR(L32="atende",L32="parcial",L32="nao_atende")),1,0) | R32: =IF(Q32=1,IF(G32=L32,1,0),"")
A33: Rio de Janeiro | B33: 44 | C33: 2026-10-17 | D33: 2.4 | E33: Endereços | F33: obrigatoria | G33: atende | H33: 0.8 | I33: Endereço encontrado(s) em 'Prefeitura da Cidade do Rio de Janeiro'. | J33: https://prefeitura.rio/ | K33: e de um atendimento personalizado ou serviços que não estão disponíveis online. Rua Afonso Cavalcanti, 455 - Cidade Nova Aplicativos Solicite diversos serviços diretamente do seu disposi | L33: atende | M33: https://prefeitura.rio/ | P33: =IF(L33="","",IF(G33="inconclusivo","Inconclusivo",IF(L33="nao_aplicavel","Aplicabilidade",IF(L33="nao_verificavel","Não verificável",IF(G33=L33,"Concordância",IF(G33="nao_atende","Falso não atende",IF(G33="atende","Falso atende","Divergência de grau"))))))) | Q33: =IF(AND(OR(G33="atende",G33="parcial",G33="nao_atende"),OR(L33="atende",L33="parcial",L33="nao_atende")),1,0) | R33: =IF(Q33=1,IF(G33=L33,1,0),"")
A34: Rio de Janeiro | B34: 44 | C34: 2026-10-17 | D34: 2.5 | E34: Telefones | F34: obrigatoria | G34: atende | H34: 0.8 | I34: Telefone encontrado(s) em 'Perguntas Frequentes – PORTAL DA TRANSPARÊNCIA RIO'. | J34: https://transparencia.prefeitura.rio/perguntas-frequentes/ | K34: Janeiro, utilizar o número 1746. Já para demais localidades, utilizar o número (21) 3460-1746. 4. Onde posso encontrar os serviços da Prefeitura do Rio? A Prefeitura disponi | L34: atende | M34: https://transparencia.prefeitura.rio/perguntas-frequentes/ | P34: =IF(L34="","",IF(G34="inconclusivo","Inconclusivo",IF(L34="nao_aplicavel","Aplicabilidade",IF(L34="nao_verificavel","Não verificável",IF(G34=L34,"Concordância",IF(G34="nao_atende","Falso não atende",IF(G34="atende","Falso atende","Divergência de grau"))))))) | Q34: =IF(AND(OR(G34="atende",G34="parcial",G34="nao_atende"),OR(L34="atende",L34="parcial",L34="nao_atende")),1,0) | R34: =IF(Q34=1,IF(G34=L34,1,0),"")
A35: Rio de Janeiro | B35: 44 | C35: 2026-10-17 | D35: 2.6 | E35: Horário de atendimento | F35: obrigatoria | G35: atende | H35: 0.75 | I35: Horário de atendimento encontrado(s) em 'Perguntas Frequentes - Lei Geral de Proteção de Dados (LGPD)'. | J35: https://lgpd.prefeitura.rio/faq/ | K35: e Dados Pessoais lgpd.smit@prefeitura.rio Telefone da Secretaria: 21 97050-5566 HORÁRIO DE ATENDIMENTO 10h às 18h DÚVIDAS, SERVIÇOS, INFORMAÇÕES OU DENÚNCIAS: ligue 1746 ou (21) 3460 | L35: atende | M35: https://ouvidoria.prefeitura.rio/ | P35: =IF(L35="","",IF(G35="inconclusivo","Inconclusivo",IF(L35="nao_aplicavel","Aplicabilidade",IF(L35="nao_verificavel","Não verificável",IF(G35=L35,"Concordância",IF(G35="nao_atende","Falso não atende",IF(G35="atende","Falso atende","Divergência de grau"))))))) | Q35: =IF(AND(OR(G35="atende",G35="parcial",G35="nao_atende"),OR(L35="atende",L35="parcial",L35="nao_atende")),1,0) | R35: =IF(Q35=1,IF(G35=L35,1,0),"")
A36: Rio de Janeiro | B36: 44 | C36: 2026-10-17 | D36: 2.9 | E36: Canal de Comunicação com cidadão do tipo ‘Fale Conosco’, que permite ao interessado comunicar-se com órgão por via eletrônica ou telefônica | F36: obrigatoria | G36: atende | H36: 0.7 | I36: Link para canal de contato encontrado; formulário não verificado (pode estar em sistema externo). | J36: https://ouvidoria.prefeitura.rio | K36: OUVIDORIA | L36: atende | M36: https://ouvidoria.prefeitura.rio/ | P36: =IF(L36="","",IF(G36="inconclusivo","Inconclusivo",IF(L36="nao_aplicavel","Aplicabilidade",IF(L36="nao_verificavel","Não verificável",IF(G36=L36,"Concordância",IF(G36="nao_atende","Falso não atende",IF(G36="atende","Falso atende","Divergência de grau"))))))) | Q36: =IF(AND(OR(G36="atende",G36="parcial",G36="nao_atende"),OR(L36="atende",L36="parcial",L36="nao_atende")),1,0) | R36: =IF(Q36=1,IF(G36=L36,1,0),"")
A37: Rio de Janeiro | B37: 44 | C37: 2026-10-17 | D37: 3.1 | E37: Valores da receita pública arrecadada | F37: essencial | G37: inconclusivo | H37: 0.45 | I37: Página de receitas cita arrecadação, mas sem tabela legível. | J37: https://transparencia.prefeitura.rio/planejamento-e-prestacao-de-contas/receitas-e-despesas/ | K37: ecutivo Municipal. O cidadão poderá ter acesso a informações sobre a execução orçamentária da receita e despesa, favorecidos e contratações realizadas. A atualização é diária com informações realizadas até o dia anterior. Mas o que é Receita Pública? Para atender às necessidades da socie | L37: atende | M37: https://www.rio.rj.gov.br/web/contasrio/dados-abertos | N37: Informação em sistema externo/consulta | O37: O Contas Rio disponibiliza receitas por órgão e por fonte e arquivos abertos de execução orçamentária; o robô não alcançou essa consulta externa. | P37: =IF(L37="","",IF(G37="inconclusivo","Inconclusivo",IF(L37="nao_aplicavel","Aplicabilidade",IF(L37="nao_verificavel","Não verificável",IF(G37=L37,"Concordância",IF(G37="nao_atende","Falso não atende",IF(G37="atende","Falso atende","Divergência de grau"))))))) | Q37: =IF(AND(OR(G37="atende",G37="parcial",G37="nao_atende"),OR(L37="atende",L37="parcial",L37="nao_atende")),1,0) | R37: =IF(Q37=1,IF(G37=L37,1,0),"")
A38: Rio de Janeiro | B38: 44 | C38: 2026-10-17 | D38: 3.5 | E38: Gravação de relatórios em diversos formatos em relação aos critérios da receita | F38: obrigatoria | G38: atende | H38: 0.85 | I38: Relatórios de receita exportáveis em odt, pdf, xls. | J38: https://transparencia.prefeitura.rio/wp-content/uploads/sites/100/2023/07/Demonstrativo-7-Estimativa-e-Compensacao-de-Renuncia-de-Receita-2026.pdf | K38: 2026 | L38: atende | M38: https://www.rio.rj.gov.br/web/contasrio/dados-abertos | P38: =IF(L38="","",IF(G38="inconclusivo","Inconclusivo",IF(L38="nao_aplicavel","Aplicabilidade",IF(L38="nao_verificavel","Não verificável",IF(G38=L38,"Concordância",IF(G38="nao_atende","Falso não atende",IF(G38="atende","Falso atende","Divergência de grau"))))))) | Q38: =IF(AND(OR(G38="atende",G38="parcial",G38="nao_atende"),OR(L38="atende",L38="parcial",L38="nao_atende")),1,0) | R38: =IF(Q38=1,IF(G38=L38,1,0),"")
A39: Rio de Janeiro | B39: 44 | C39: 2026-10-17 | D39: 4.1 | E39: Número e o valor de empenho, liquidação e pagamento | F39: essencial | G39: inconclusivo | H39: 0.45 | I39: Página de despesas cita as três fases, mas os dados não estão em tabela legível (provável consulta dinâmica). | J39: https://transparencia.prefeitura.rio/planejamento-e-prestacao-de-contas/receitas-e-despesas/ | K39: a Despesa Pública? Significa realizar as despesas previstas no orçamento público, seguindo os três estágios presentes na Lei nº 4.32019/64: empenho, liquidação e pagamento. O empenho é a etapa em que o governo reserva o dinheiro que será pago quando o bem for entregue ou o serviço conc | L39: parcial | M39: https://www.rio.rj.gov.br/web/contasrio/dados-abertos | N39: Informação em sistema externo/consulta | O39: Contas Rio oferece consultas separadas de empenhos, liquidação e pagamentos. Não foi possível conferir o número e valor de cada fase em um mesmo registro. | P39: =IF(L39="","",IF(G39="inconclusivo","Inconclusivo",IF(L39="nao_aplicavel","Aplicabilidade",IF(L39="nao_verificavel","Não verificável",IF(G39=L39,"Concordância",IF(G39="nao_atende","Falso não atende",IF(G39="atende","Falso atende","Divergência de grau"))))))) | Q39: =IF(AND(OR(G39="atende",G39="parcial",G39="nao_atende"),OR(L39="atende",L39="parcial",L39="nao_atende")),1,0) | R39: =IF(Q39=1,IF(G39=L39,1,0),"")
A40: Rio de Janeiro | B40: 44 | C40: 2026-10-17 | D40: 4.5 | E40: Gravação de relatórios em diversos formatos em relação aos critérios da despesa | F40: obrigatoria | G40: inconclusivo | H40: 0.4 | I40: Exportação de relatórios de despesa não encontrada nas páginas visitadas, mas elas apontam para 3 link(s) de sistema externo não visitado(s) (ex.: www.rio.rj.gov.br). | J40: https://www.rio.rj.gov.br/web/contasrio | K40: ACESSE O NOVO PORTAL CONTAS RIO | L40: atende | M40: https://transparencia.prefeitura.rio/dados-abertos/ | N40: Informação em sistema externo/consulta | O40: O Portal da Transparência aponta o Contas Rio com downloads em CSV e TXT de execução de despesas e liquidações. | P40: =IF(L40="","",IF(G40="inconclusivo","Inconclusivo",IF(L40="nao_aplicavel","Aplicabilidade",IF(L40="nao_verificavel","Não verificável",IF(G40=L40,"Concordância",IF(G40="nao_atende","Falso não atende",IF(G40="atende","Falso atende","Divergência de grau"))))))) | Q40: =IF(AND(OR(G40="atende",G40="parcial",G40="nao_atende"),OR(L40="atende",L40="parcial",L40="nao_atende")),1,0) | R40: =IF(Q40=1,IF(G40=L40,1,0),"")
...

Sheet Listas
A1: Crawler não chegou à página
A2: Informação em sistema externo/consulta
A3: Conteúdo dinâmico (JavaScript)
A4: Regra: padrão não reconhecido
A5: Regra: falso indício
A6: Critério ambíguo
A7: Página indisponível
A8: Outro

Sheet Ajustes
A1: Data | B1: Critério | C1: Problema observado | D1: Ajuste feito | E1: Regra antes | F1: Regra depois | G1: Efeito na concordância
